Workbook

Sheet Summary
B2: AtliQ Sales and CRM Assistant: monthly running cost estimate (Capstone 1, Step 4)
B3: Author: Ashokkumar, AI Product Manager. Builds on the AI PRD and the AI Opportunity Map. Updated 4 Oct 2026 to match the Step 5 prototype: GPT-OSS models on Groq, no embeddings, no database in the prototype. Prices checked 4 Oct 2026 on the providers' official pages (see 'Sources & Assumptions'). All figures in USD.
B5: Cost line | C5: Model / service | D5: Calls per month | E5: Cost per month | F5: Notes
B6: F1 Capture & Link (linking, triage, draft leads) | C6: GPT-OSS 20B on Groq, prompt caching | D6: ='Inference (Groq)'!$D$14 -> 1645.6 | E6: ='Inference (Groq)'!$K$14 -> 0.36056592 | F6: Every client message and note. Deterministic matching first; the model resolves fuzzy cases, drafts new leads and flags which sources carry a commitment.
B7: F2 Commitment & Signal Ledger (extraction + CRM update proposals) | C7: GPT-OSS 120B on Groq, prompt caching | D7: ='Inference (Groq)'!$D$15 -> 658.24 | E7: ='Inference (Groq)'!$K$15 -> 0.78608218 | F7: Only sources flagged by F1 (~40%). Strict JSON-schema output; quotes are verified in code, so a cheaper model is safe here.
B8: F3 Daily Brief (one-line summaries) | C8: GPT-OSS 120B on Groq, real time | D8: ='Inference (Groq)'!$D$16 -> 88 | E8: ='Inference (Groq)'!$K$16 -> 0.07491 | F8: Ranking is code; the model restates ledger facts. Real time because Groq's Batch API has a 24-hour minimum window and is off under zero data retention.
B9: F3 Pipeline review pack | C9: GPT-OSS 120B on Groq, real time | D9: ='Inference (Groq)'!$D$17 -> 5 | E9: ='Inference (Groq)'!$K$17 -> 0.024225 | F9: Weekly and monthly pack for the founders' review.
B10: F4 Reply drafts (copy only, never sent) | C10: GPT-OSS 120B on Groq, prompt caching | D10: ='Inference (Groq)'!$D$18 -> 330 | E10: ='Inference (Groq)'!$K$18 -> 0.2707335 | F10: On demand from the brief; per-account context only. Unsafe drafts are retried once, then withheld.
B11: Embeddings | C11: None | D11: 0 | E11: 0 | F11: Not used: rules plus the F1 model linked 50 of 50 dataset sources. Voyage kept as an option (see 'Embeddings').
B12: Buffer for retries, weekly eval re-runs and prompt growth | C12: 25% of AI cost | E12: =0.25*SUM(E6:E11) -> 0.37912915 | F12: Covers the weekly audit of 10 threads, re-running the 50-file eval set before each rollout gate, and failed calls.
B13: AI subtotal | D13: =SUM(D6:D11) -> 2726.84 | E13: =SUM(E6:E12) -> 1.8956457 | F13: Variable cost: grows roughly in line with message volume.
B14: Vercel Pro (1 seat) + Supabase Pro | C14: Hosting, database, cron | E14: =Infrastructure!$D$10 -> 45 | F14: Fixed cost. The prototype runs on Vercel Hobby with no database ($0); commercial use for AtliQ needs Vercel Pro, and the 12-month audit log needs a real database (see Infrastructure).
B15: MVP TOTAL PER MONTH | C15: F1 to F4, 4 sellers | E15: =E13+E14 -> 46.895646
B16: MVP COST PER SELLER PER MONTH | E16: =E15/'Volume Sizing'!$D$6 -> 11.723911
B17: AI cost per seller per month (excluding fixed hosting) | E17: =E13/'Volume Sizing'!$D$6 -> 0.47391144 | F17: What each additional seller would add (fixed hosting is shared).
B19: Post-MVP add-on: Voice capture (O8) | C19: Whisper large v3 turbo + GPT-OSS 120B on Groq | D19: ='Inference (Groq)'!$D$19 -> 176 | E19: =1.25*'Inference (Groq)'!$K$26 -> 0.4847425 | F19: 2 voice notes per seller per workday, 1.5 minutes each; includes the 25% buffer.
B20: Total per month with voice capture | E20: =E15+E19 -> 47.380388 | F20: ="Per seller: $"&TEXT(E20/'Volume Sizing'!$D$6,"0.00") -> Per seller: $11.85
B22: How cost shaped the model choices (monthly AI cost, before buffer and hosting)
B23: Scenario | E23: AI cost / month | F23: What it tells us
B24: Chosen mix (GPT-OSS 20B for linking; 120B for extraction, brief, pack and drafts; prompt caching) | E24: =SUM(E6:E10) -> 1.5165166 | F24: The MVP plan above, as the prototype runs it.
B25: Previous plan: Claude Haiku 4.5 + Sonnet 5.5, caching and batch | E25: ='Inference (Groq)'!$K$32 -> 12.572748 | F25: The Step 4 plan before the prototype moved to Groq. About eight times the chosen mix, though still small next to hosting.
B26: Everything on Claude Sonnet 5.5, no caching | E26: =Inference!K26+Inference!K7+Inference!K45+Inference!K64+Inference!K83 -> 20.04643 | F26: The fallback if GPT-OSS quality drops on real mail: the Claude path is still in the code (set ANTHROPIC_API_KEY).
B27: Everything on GPT-OSS 120B (no 20B triage) | E27: ='Inference (Groq)'!$K$29 -> 1.8770825 | F27: Cents more than the chosen mix; an option if the 20B model's linking proves unreliable.
B28: Chosen mix, but no F1 triage gate (every source goes to extraction) | E28: ='Inference (Groq)'!$K$30 -> 2.6956399 | F28: The 'has commitment' flag still cuts the extraction volume by 60%.
B29: Chosen mix, raw threads with quoted history and signatures (about 4x source tokens) | E29: ='Inference (Groq)'!$K$31 -> 1.7738866 | F29: Why pre-processing strips signatures and quoted replies before any model call, and why extraction tokens per source are capped (PRD NFR 'Cost').
B30: Chosen mix at 3x volume (12 sellers or a busier inbox) | E30: =3*SUM(E6:E10) -> 4.5495498 | F30: Still small next to hosting; the design scales without a model change.
B32: Cost as a product decision: what it changed in scope
B33: Decision | E33: Effect on cost | F33: Effect on the product
B34: Two-tier models: GPT-OSS 20B gates every source, 120B only on sources with a commitment and on everything a seller reads | E34: Roughly halves F1 cost versus running it on 120B | F34: Keeps the stronger model where recall and quotes matter (the North Star) and the cheap one for volume.
B35: Deterministic code for ranking, due dates, duplicate thresholds and exact matches | E35: Removes calls entirely | F35: Also makes the brief explainable: the ranking rule is shown, not guessed by a model.
B36: Prompt caching on the static schema, rules and few-shot prefix (Groq: automatic, 50% off cached input, 2-hour expiry) | E36: About 15% off F2 (output and reasoning tokens dominate); less on drafts | F36: Lets us keep rich few-shot examples (better recall) without paying full price on every call. No code change needed.
B37: No Batch API for the brief and review pack | E37: Gives up 50% on lines that cost cents | F37: Groq's batch window is 24 hours minimum (too slow for the 08:00 brief) and batch needs data retention, which zero data retention switches off.
B38: CRM update proposals come out of the F2 extraction call | E38: No extra calls for F4 proposals | F38: One source of truth: every proposal cites the same quote as its ledger item.
B39: Strip signatures and quoted history; cap tokens per source | E39: Avoids roughly 4x token growth | F39: Also stops old quoted text being extracted twice as a new commitment.
B40: No RAG chatbot, no web enrichment, no lead scoring | E40: Avoids open-ended query volume | F40: Matches the PRD's out-of-scope list; the pain is forgetting, not searching.
B41: Voice capture deferred to after MVP | E41: Adds about the cost shown above when switched on | F41: Cheap enough to be first after MVP; the seller picks the account in the app, so no linking call is needed.
B42: Provider switched from Claude to Groq after the prototype | E42: About 88% off inference | F42: Same grounding checks in code, so quality risk is caught by the evals. Trade-offs: US data processing and occasional date slips; Claude stays as a coded fallback.
B43: Prototype phase (Step 5, one-off)
B44: Item | D44: Quantity | E44: Cost | F44: Basis
B45: One full run over the dataset (50 files, 4 briefs, 1 pack, 20 drafts) | D45: 1 | E45: =50*('Inference (Groq)'!$J$14+'Inference (Groq)'!$J$15)+4*'Inference (Groq)'!$J$16+'Inference (Groq)'!$J$17+20*'Inference (Groq)'!$J$18 -> 0.095324455 | F45: Every dataset file goes through both F1 and F2, priced on Groq. The committed demo outputs were generated with Claude during the build.
...

Sheet Volume Sizing
B2: Volume sizing: from the Dataset to a realistic month (4 sellers)
B3: Dataset measured on 3 Oct 2026 (word counts of every file in Dataset/emails and Dataset/meeting_notes). Yellow cells are assumptions you can change; everything else is a formula. Row 30 applies to the Claude comparison only; GPT-OSS uses 1.3 tokens per word ('Inference (Groq)'!C10).
B5: Measure | C5: Dataset (measured) | D5: Realistic month (base case) | E5: How it was scaled
B6: Sellers using the brief | C6: 4 | D6: 4 | E6: Bhavin, Dhaval, Karandeep, Jay (Pranav and Ayush only receive routed tasks).
B7: CRM accounts | C7: 40 | D7: 200 | E7: PRD NFR 'Scalability': sized for about 200 accounts, roughly 50 per seller.
B8: Email threads in the dataset | C8: 34 | E8: 25 of them fall in the active window 3 Jun to 8 Jul 2026 (about 5 weeks).
B9: Average words per email | C9: 134 | D9: 150 | E9: Measured 134 (min 57, max 182) per curated thread. Real messages run longer, but pre-processing strips signatures and quoted history, so 150 words per new message.
B10: Meeting notes in the dataset | C10: 16 | E10: 14 of them fall in the 3 Jun to 9 Jul window.
B11: Average words per meeting note | C11: 99 | D11: 120 | E11: Measured 99 (min 29, max 181). Allow for longer QBR-style notes.
B12: Dataset run-rate: email threads per month | C12: =25/5*4.33 -> 21.65 | E12: 25 threads in about 5 weeks, times 4.33 weeks per month. This only covers the ~40 tracked accounts and one message per thread.
B13: Dataset run-rate: meeting notes per month | C13: =14/5*4.33 -> 12.124 | E13: 14 notes in about 5 weeks.
B14: Client and prospect messages per seller per workday | D14: 17 | E14: Sent plus received, after a deterministic filter drops internal mail, newsletters and auto-replies by domain. Matches the PRD NFR of about 1,500 emails a month.
B15: Meeting notes per seller per workday | D15: 1.7 | E15: About 8 to 9 client meetings or calls per seller per week, matching the PRD NFR of about 150 notes a month.
B16: Workdays per month | D16: 22 | E16: Daily brief and ingestion run on AtliQ business days.
B17: Client messages per month | D17: =D6*D14*D16 -> 1496 | E17: Sellers x messages per day x workdays.
B18: Meeting notes per month | D18: =D6*D15*D16 -> 149.6 | E18: Sellers x notes per day x workdays.
B19: Total sources per month (every one gets the F1 linking pass) | D19: =D17+D18 -> 1645.6
B20: Weighted average words per source | D20: =(D17*D9+D18*D11)/D19 -> 147.27273
B21: Share of sources carrying an ask, promise or signal | D21: 0.4 | E21: In the curated dataset almost every file carries an item; in a real mailbox many messages are 'thanks' or scheduling noise. F1 flags these so only ~40% go to the more expensive F2 extraction.
B22: Sources sent to F2 extraction per month | D22: =D19*D21 -> 658.24
B23: Reply drafts requested per seller per workday | D23: 3 | E23: Dataset shows 37 asks and promises in 5 weeks for 40 accounts (Appendix A); x5 accounts gives about 160 a month, and sellers also ask for drafts on follow-ups.
B24: Draft regenerations (share of drafts) | D24: 0.25 | E24: Seller asks for a second version.
B25: Reply drafts per month | D25: =D6*D23*D16*(1+D24) -> 330
B26: Daily briefs per month | D26: =D6*D16 -> 88 | E26: One per seller per workday at 08:00 IST.
B27: Pipeline review packs per month | D27: 5 | E27: Weekly pack plus the monthly review pack.
B28: Voice notes per seller per workday (post-MVP) | D28: 2 | E28: Quick capture after a call or meeting (O8, first feature after MVP).
B29: Average minutes per voice note (post-MVP) | D29: 1.5
B30: Claude tokens per word | C30: 1.3 | D30: =1.3*1.3 -> 1.69 | E30: Template uses 1.3 tokens per word. Anthropic's pricing page says Claude 4.7 and later models use a tokenizer that produces about 30% more tokens, so 1.69 is used for every Claude task (slightly conservative for Haiku 4.5).
B31: Cross-check: dataset-derived commitment-bearing messages per month | D31: =C12*(D7/C7)*4 -> 433 | E31: Dataset run-rate x5 accounts x about 4 messages per thread. About two-thirds of the F2 volume above, so the base case is consistent with the dataset and carries about 50% headroom.

Sheet Inference
B2: Claude option (previous plan, kept for comparison): inference cost per AI task on the Claude API. Prices from platform.claude.com/docs/en/about-claude/pricing, checked 3 Oct 2026. The chosen stack is on 'Inference (Groq)', which reuses the prompt sizes below.
B4: Base Calculation: F2 Commitment & Signal Ledger: extraction (real time) | E4: Model Selection + Cost Estimation: F2 Commitment & Signal Ledger: extraction (real time)
B5: Description | C5: Quantity | E5: Model Name | F5: Input cost($) per 1M token | G5: Output cost($) per 1M token | H5: Cost per input Query($) | I5: Cost per output query Query($) | J5: Total Cost per query | K5: Total cost per month | L5: Cache read ($) per 1M token | M5: Min. cacheable prefix (tokens) | N5: Cost per query with caching ($) | O5: Total cost per month with caching
B6: Source message (new email or note, stripped) - avg words x 1.69 + 40 header tokens | C6: ='Volume Sizing'!$D$20*'Volume Sizing'!$D$30+40 -> 288.89091 | E6: Claude Haiku 4.5 | F6: 1 | G6: 5 | H6: =F6*$C$11/1000000 -> 0.0043488909 | I6: =G6*$C$12/1000000 -> 0.0025 | J6: =H6+I6 -> 0.0068488909 | K6: =Table2[[#This Row],[Total Cost per query]]*$C$16 -> 4.508214 | L6: 0.1 | M6: 4096 | N6: =IF(AND($C$17>0,$C$17>=M6),(($C$11-$C$17)*F6+$C$17*($C$18*L6+(1-$C$18)*F6*$C$19))/1000000+I6,J6) -> 0.0068488909 | O6: =N6*$C$16 -> 4.508214
B7: System prompt, ledger schema and guardrail rules (cached) | C7: 1800 | E7: Claude Sonnet 5.5 << Claude plan | F7: 2 | G7: 10 | H7: =F7*$C$11/1000000 -> 0.0086977818 | I7: =G7*$C$12/1000000 -> 0.005 | J7: =H7+I7 -> 0.013697782 | K7: =Table2[[#This Row],[Total Cost per query]]*$C$16 -> 9.0164279 | L7: 0.2 | M7: 512 | N7: =IF(AND($C$17>0,$C$17>=M7),(($C$11-$C$17)*F7+$C$17*($C$18*L7+(1-$C$18)*F7*$C$19))/1000000+I7,J7) -> 0.0088697818 | O7: =N7*$C$16 -> 5.8384452
B8: Few-shot examples from Appendix A (cached) | C8: 1500 | E8: Claude Opus 5.5 | F8: 4 | G8: 20 | H8: =F8*$C$11/1000000 -> 0.017395564 | I8: =G8*$C$12/1000000 -> 0.01 | J8: =H8+I8 -> 0.027395564 | K8: =Table2[[#This Row],[Total Cost per query]]*$C$16 -> 18.032856 | L8: 0.2 | M8: 512 | N8: =IF(AND($C$17>0,$C$17>=M8),(($C$11-$C$17)*F8+$C$17*($C$18*L8+(1-$C$18)*F8*$C$19))/1000000+I8,J8) -> 0.017127564 | O8: =N8*$C$16 -> 11.274047
B9: Account context: CRM record + open ledger rows for this account | C9: 660
B10: Team directory and reference date (cached) | C10: 100 | E10: Claude plan, monthly cost | F10: Claude Sonnet 5.5 | O10: =O7 -> 5.8384452
B11: Total input tokens per query | C11: =SUM(C6:C10) -> 4348.8909 | E11: Claude plan, cost per query | F11: =N7 -> 0.0088697818
B12: Total Output tokens per query | C12: 500
B13: Total Token per query | C13: =C11+C12 -> 4848.8909
B14: Total queries received per day | C14: ='Volume Sizing'!$D$22/'Volume Sizing'!$D$16 -> 29.92
B15: Total number of days per month | C15: ='Volume Sizing'!$D$16 -> 22
B16: Total monthly volume of queries | C16: =C14*C15 -> 658.24
B17: Cacheable static prefix (tokens) | C17: =C7+C8+C10 -> 3400
B18: Expected cache-hit rate | C18: 0.9
B19: Cache write multiplier (1-hour cache = 2x) | C19: 2
B20: Why Sonnet 5.5: this step decides the North Star. Recall must be at least 90% and every item needs a verbatim quote, so a mid-tier model with reliable JSON is worth 2x Haiku. Opus 5.5 costs 2x Sonnet for a gain the evals have not shown is needed. Haiku 4.5 is the fallback: if it matches Sonnet on the Appendix A eval set in alpha, switch and save about half of this line. Real time (not Batch) because the PRD needs a new email linked and extracted within 15 minutes. Output (~2.5 items x 140 tokens + proposed CRM field changes) also carries the F4 CRM update proposals, so they need no extra call. Caching: the 3,400-token static prefix uses the 1-hour cache (2x write, 0.1x read); about 30 calls a workday keep it warm, so ~90% are hits. Haiku 4.5 cannot cache it (minimum 4,096 tokens).
B23: Base Calculation: F1 Capture & Link: account linking and triage (real time) | E23: Model Selection + Cost Estimation: F1 Capture & Link: account linking and triage (real time)
B24: Description | C24: Quantity (tokens) | E24: Model Name | F24: Input cost($) per 1M token | G24: Output cost($) per 1M token | H24: Cost per input Query($) | I24: Cost per output query Query($) | J24: Total Cost per query | K24: Total cost per month | L24: Cache read ($) per 1M token | M24: Min. cacheable prefix (tokens) | N24: Cost per query with caching ($) | O24: Total cost per month with caching
B25: Source message (new email or note, stripped) | C25: ='Volume Sizing'!$D$20*'Volume Sizing'!$D$30+40 -> 288.89091 | E25: Claude Haiku 4.5 << Claude plan | F25: 1 | G25: 5 | H25: =F25*$C$30/1000000 -> 0.0015388909 | I25: =G25*$C$31/1000000 -> 0.00075 | J25: =H25+I25 -> 0.0022888909 | K25: =J25*$C$35 -> 3.7665989 | L25: 0.1 | M25: 4096 | N25: =IF(AND($C$36>0,$C$36>=M25),(($C$30-$C$36)*F25+$C$36*($C$37*L25+(1-$C$37)*F25*$C$38))/1000000+I25,J25) -> 0.0022888909 | O25: =N25*$C$35 -> 3.7665989
B26: System prompt and output schema | C26: 700 | E26: Claude Sonnet 5.5 | F26: 2 | G26: 10 | H26: =F26*$C$30/1000000 -> 0.0030777818 | I26: =G26*$C$31/1000000 -> 0.0015 | J26: =H26+I26 -> 0.0045777818 | K26: =J26*$C$35 -> 7.5331978 | L26: 0.2 | M26: 512 | N26: =IF(AND($C$36>0,$C$36>=M26),(($C$30-$C$36)*F26+$C$36*($C$37*L26+(1-$C$37)*F26*$C$38))/1000000+I26,J26) -> 0.0034417818 | O26: =N26*$C$35 -> 5.6637962
B27: Candidate accounts shortlist (top 5 from deterministic + embedding match) | C27: 300 | E27: Claude Opus 5.5 | F27: 4 | G27: 20 | H27: =F27*$C$30/1000000 -> 0.0061555636 | I27: =G27*$C$31/1000000 -> 0.003 | J27: =H27+I27 -> 0.0091555636 | K27: =J27*$C$35 -> 15.066396 | L27: 0.2 | M27: 512 | N27: =IF(AND($C$36>0,$C$36>=M27),(($C$30-$C$36)*F27+$C$36*($C$37*L27+(1-$C$37)*F27*$C$38))/1000000+I27,J27) -> 0.0067395636 | O27: =N27*$C$35 -> 11.090626
B28: Team directory and AtliQ domains | C28: 100
B29: Possible duplicate CRM rows (for the merge flag) | C29: 150 | E29: Claude plan, monthly cost | F29: Claude Haiku 4.5 | O29: =O25 -> 3.7665989
B30: Total input tokens per query | C30: =SUM(C25:C29) -> 1538.8909 | E30: Claude plan, cost per query | F30: =N25 -> 0.0022888909
B31: Total Output tokens per query | C31: 150
B32: Total Token per query | C32: =C30+C31 -> 1688.8909
B33: Total queries received per day | C33: ='Volume Sizing'!$D$19/'Volume Sizing'!$D$16 -> 74.8
B34: Total number of days per month | C34: ='Volume Sizing'!$D$16 -> 22
B35: Total monthly volume of queries | C35: =C33*C34 -> 1645.6
B36: Cacheable static prefix (tokens) | C36: =C26+C28 -> 800
B37: Expected cache-hit rate | C37: 0.9
B38: Cache write multiplier (1-hour cache = 2x) | C38: 2
B39: Why Haiku 4.5: exact matches on contact email, domain and lead_id are done in code first; the model only resolves fuzzy names ('Meridian Health LLC' vs 'Meridian Healthcare'), drafts new leads, flags duplicates and sets a 'has commitment' flag. That is short classification against a 5-row shortlist, the highest-volume call, and the cheapest model is enough. The 'has commitment' flag is the main cost lever: only ~40% of sources go on to the Sonnet extraction. No caching: the 800-token prefix is below Haiku's 4,096-token minimum.
B42: Base Calculation: F3 Daily Brief: one-line summaries (nightly, Batch API) | E42: Model Selection + Cost Estimation: F3 Daily Brief: one-line summaries (nightly, Batch API)
B43: Description | C43: Quantity (tokens) | E43: Model Name | F43: Batch input cost($) per 1M token | G43: Batch output cost($) per 1M token | H43: Cost per input Query($) | I43: Cost per output query Query($) | J43: Total Cost per query | K43: Total cost per month | L43: Cache read ($) per 1M token | M43: Min. cacheable prefix (tokens) | N43: Cost per query with caching ($) | O43: Total cost per month with caching
B44: Seller's top 10 ranked ledger items (10 x 150 tokens) | C44: 1500 | E44: Claude Haiku 4.5 (Batch API) << Claude plan | F44: 0.5 | G44: 2.5 | H44: =F44*$C$49/1000000 -> 0.0013 | I44: =G44*$C$50/1000000 -> 0.001 | J44: =H44+I44 -> 0.0023 | K44: =J44*$C$54 -> 0.2024 | L44: 0.05 | M44: 4096 | N44: =IF(AND($C$55>0,$C$55>=M44),(($C$49-$C$55)*F44+$C$55*($C$56*L44+(1-$C$56)*F44*$C$57))/1000000+I44,J44) -> 0.0023 | O44: =N44*$C$54 -> 0.2024
B45: System prompt and style rules | C45: 500 | E45: Claude Sonnet 5.5 (Batch API) | F45: 1 | G45: 5 | H45: =F45*$C$49/1000000 -> 0.0026 | I45: =G45*$C$50/1000000 -> 0.002 | J45: =H45+I45 -> 0.0046 | K45: =J45*$C$54 -> 0.4048 | L45: 0.1 | M45: 512 | N45: =IF(AND($C$55>0,$C$55>=M45),(($C$49-$C$55)*F45+$C$55*($C$56*L45+(1-$C$56)*F45*$C$57))/1000000+I45,J45) -> 0.0046 | O45: =N45*$C$54 -> 0.4048
B46: Unassigned items shown on founders' briefs (3 x 150) | C46: 450 | E46: Claude Opus 5.5 (Batch API) | F46: 2 | G46: 10 | H46: =F46*$C$49/1000000 -> 0.0052 | I46: =G46*$C$50/1000000 -> 0.004 | J46: =H46+I46 -> 0.0092 | K46: =J46*$C$54 -> 0.8096 | L46: 0.1 | M46: 512 | N46: =IF(AND($C$55>0,$C$55>=M46),(($C$49-$C$55)*F46+$C$55*($C$56*L46+(1-$C$56)*F46*$C$57))/1000000+I46,J46) -> 0.0092 | O46: =N46*$C$54 -> 0.8096
...

Sheet Inference (Groq)
B2: Inference cost on Groq: the stack the Step 5 prototype runs on (chosen plan)
B3: Prices from Groq's model pages (console.groq.com/docs/model/...), checked 4 Oct 2026. Token counts reuse the prompt sizes on the 'Inference' sheet; source text is re-tokenised at 1.3 tokens per word for GPT-OSS. Yellow cells are assumptions to replace with measured usage from the prototype logs.
B5: Model on Groq | C5: Input $ per 1M tokens | D5: Cached input $ per 1M | E5: Output $ per 1M tokens
B6: openai/gpt-oss-20b | C6: 0.075 | D6: 0.0375 | E6: 0.3 | L6: Cached input is 50% of input. Caching is automatic for GPT-OSS models, has no write fee, and expires after 2 hours unused.
B7: openai/gpt-oss-120b | C7: 0.15 | D7: 0.075 | E7: 0.6 | L7: GPT-OSS models are reasoning models: reasoning tokens are billed as output, so an allowance is added per call below.
B8: whisper-large-v3-turbo (speech to text), $ per audio hour | C8: 0.04
B10: GPT-OSS tokens per word | C10: 1.3 | L10: GPT-OSS uses OpenAI's o200k tokenizer; about 1.3 tokens per English word (the Claude sheet uses 1.69).
B11: Source message tokens (stripped email or note, avg words x tokens per word + 40 header) | C11: ='Volume Sizing'!$D$20*$C$10+40 -> 231.45455
B13: Task | C13: Model | D13: Calls per month | E13: Input tokens per call | F13: Of which cacheable prefix | G13: Cache-hit rate | H13: Visible output tokens | I13: Reasoning tokens (allowance) | J13: Cost per call | K13: Cost per month | L13: Notes
B14: F1 Capture & Link: linking triage and draft leads | C14: openai/gpt-oss-20b | D14: ='Volume Sizing'!$D$19 -> 1645.6 | E14: =$C$11+Inference!$C$26+Inference!$C$27+Inference!$C$28+Inference!$C$29 -> 1481.4545 | F14: =Inference!$C$26+Inference!$C$28 -> 800 | G14: 0.9 | H14: =Inference!$C$31 -> 150 | I14: 300 | J14: =(($E14-$F14*$G14)*VLOOKUP($C14,$B$6:$E$7,2,FALSE)+$F14*$G14*VLOOKUP($C14,$B$6:$E$7,3,FALSE)+($H14+$I14)*VLOOKUP($C14,$B$6:$E$7,4,FALSE))/1000000 -> 0.00021910909 | K14: =$J14*$D14 -> 0.36056592 | L14: Rules link exact matches first (contact email, domain, lead_id, company name); the model resolves only what they cannot. In the prototype this pass is gpt-oss-20b.
B15: F2 Commitment & Signal Ledger: extraction + CRM proposals | C15: openai/gpt-oss-120b | D15: ='Volume Sizing'!$D$22 -> 658.24 | E15: =$C$11+Inference!$C$7+Inference!$C$8+Inference!$C$9+Inference!$C$10 -> 4291.4545 | F15: =Inference!$C$7+Inference!$C$8+Inference!$C$10 -> 3400 | G15: 0.9 | H15: =Inference!$C$12 -> 500 | I15: 800 | J15: =(($E15-$F15*$G15)*VLOOKUP($C15,$B$6:$E$7,2,FALSE)+$F15*$G15*VLOOKUP($C15,$B$6:$E$7,3,FALSE)+($H15+$I15)*VLOOKUP($C15,$B$6:$E$7,4,FALSE))/1000000 -> 0.0011942182 | K15: =$J15*$D15 -> 0.78608218 | L15: Strict JSON-schema output; every quote re-checked in code. Only sources the F1 pass flags (~40%) reach this step.
B16: F3 Daily Brief: one-line summaries (real time) | C16: openai/gpt-oss-120b | D16: ='Volume Sizing'!$D$26 -> 88 | E16: =Inference!$C$49 -> 2600 | F16: =Inference!$C$45 -> 500 | G16: 0.5 | H16: =Inference!$C$50 -> 400 | I16: 400 | J16: =(($E16-$F16*$G16)*VLOOKUP($C16,$B$6:$E$7,2,FALSE)+$F16*$G16*VLOOKUP($C16,$B$6:$E$7,3,FALSE)+($H16+$I16)*VLOOKUP($C16,$B$6:$E$7,4,FALSE))/1000000 -> 0.00085125 | K16: =$J16*$D16 -> 0.07491 | L16: Moved from the 20B to the 120B model after the 20B model skipped items in prototype testing. No Batch API: Groq's batch window is 24 hours minimum and is disabled under zero data retention.
B17: F3 Pipeline review pack (weekly and monthly, real time) | C17: openai/gpt-oss-120b | D17: ='Volume Sizing'!$D$27 -> 5 | E17: =Inference!$C$68 -> 16300 | F17: =Inference!$C$64 -> 1000 | G17: 0 | H17: =Inference!$C$69 -> 2500 | I17: 1500 | J17: =(($E17-$F17*$G17)*VLOOKUP($C17,$B$6:$E$7,2,FALSE)+$F17*$G17*VLOOKUP($C17,$B$6:$E$7,3,FALSE)+($H17+$I17)*VLOOKUP($C17,$B$6:$E$7,4,FALSE))/1000000 -> 0.004845 | K17: =$J17*$D17 -> 0.024225 | L17: Five runs a month, so caching does not apply (2-hour expiry).
B18: F4 Reply drafts (copy only, never sent) | C18: openai/gpt-oss-120b | D18: ='Volume Sizing'!$D$25 -> 330 | E18: =3*$C$11+Inference!$C$83+Inference!$C$84+Inference!$C$85+Inference!$C$86 -> 2794.3636 | F18: =Inference!$C$83 -> 1500 | G18: 0.7 | H18: =Inference!$C$88 -> 300 | I18: 500 | J18: =(($E18-$F18*$G18)*VLOOKUP($C18,$B$6:$E$7,2,FALSE)+$F18*$G18*VLOOKUP($C18,$B$6:$E$7,3,FALSE)+($H18+$I18)*VLOOKUP($C18,$B$6:$E$7,4,FALSE))/1000000 -> 0.00082040455 | K18: =$J18*$D18 -> 0.2707335 | L18: Per-account context only. Unsafe drafts are retried once with the reasons, so allow ~10% extra calls inside the 25% buffer.
B19: Post-MVP: voice capture extraction from the transcript | C19: openai/gpt-oss-120b | D19: =Inference!$C$111 -> 176 | E19: ='Volume Sizing'!$D$29*150*$C$10+Inference!$C$102+Inference!$C$103+Inference!$C$104+Inference!$C$105 -> 4352.5 | F19: =Inference!$C$102+Inference!$C$103+Inference!$C$105 -> 3400 | G19: 0.9 | H19: =Inference!$C$107 -> 500 | I19: 800 | J19: =(($E19-$F19*$G19)*VLOOKUP($C19,$B$6:$E$7,2,FALSE)+$F19*$G19*VLOOKUP($C19,$B$6:$E$7,3,FALSE)+($H19+$I19)*VLOOKUP($C19,$B$6:$E$7,4,FALSE))/1000000 -> 0.001203375 | K19: =$J19*$D19 -> 0.211794 | L19: Not in the MVP total. Same prompt as F2, run on the transcript.
B21: MVP inference on Groq per month (F1 to F4, before buffer) | K21: =SUM(K14:K18) -> 1.5165166
B23: Voice capture speech to text (post-MVP)
B24: Audio minutes per month | K24: =Inference!$C$120 -> 264
B25: Speech-to-text cost per month (whisper-large-v3-turbo, $ per hour / 60) | K25: =K24*$C$8/60 -> 0.176 | L25: Groq bills each transcription request for at least 10 seconds; 90-second notes are well above that.
B26: Voice capture add-on per month (extraction + speech to text) | K26: =K19+K25 -> 0.387794
B28: Comparisons (monthly inference, before buffer)
B29: Everything on gpt-oss-120b (no 20B triage) | K29: =K21-K14+D14*((E14-F14*G14)*$C$7+F14*G14*$D$7+(H14+I14)*$E$7)/1000000 -> 1.8770825
B30: Chosen mix, but no F1 gate (every source goes to F2 extraction) | K30: =K21-K15+J15*'Volume Sizing'!$D$19 -> 2.6956399
B31: Chosen mix, raw threads with quoted history and signatures (about 4x source tokens) | K31: =K21+3*($C$11*(D14*$C$6+D15*$C$7+D18*3*$C$7))/1000000 -> 1.7738866
B32: Previous plan: Claude Haiku 4.5 + Sonnet 5.5 with caching and batch ('Inference' sheet) | K32: =Inference!$O$29+Inference!$O$10+Inference!$O$48+Inference!$O$67+Inference!$O$86 -> 12.572748
B34: Why Groq and GPT-OSS: the live prototype already runs on them and passed the PRD evals on the dataset with the same grounding checks in code. They cost about an eighth of the Claude plan. Risks to watch: the 20B model skipped brief items in testing (moved to 120B), extraction read 'by Wednesday' a day early once (the two-business-day rule caught it), and Groq processes data in the US. The Claude path stays in the code as a fallback.

Sheet Embeddings
C2: Not used in the prototype or the updated MVP plan: deterministic linking (contact email, domain, lead_id, company name) plus the model linked 50 of 50 dataset sources correctly. Kept as an option if fuzzy matching degrades at 200+ accounts.
C3: Token/word | D3: 1.3
C5: Emails (per month) | F5: Meeting notes (per month) | I5: CRM accounts + ledger items
C6: Component | D6: Quantity | F6: Component | G6: Quantity | I6: Component | J6: Quantity
C7: Number of emails | D7: ='Volume Sizing'!$D$17 -> 1496 | F7: Number of meeting notes | G7: ='Volume Sizing'!$D$18 -> 149.6 | I7: Accounts + new ledger items | J7: ='Volume Sizing'!$D$7+'Volume Sizing'!$D$22*2.5 -> 1845.6
C8: Number of words per email | D8: ='Volume Sizing'!$D$9 -> 150 | F8: Number of words per note | G8: ='Volume Sizing'!$D$11 -> 120 | I8: Number of words per record | J8: 40
C9: Total number of words | D9: =D7*D8 -> 224400 | F9: Total number of words | G9: =G8*G7 -> 17952 | I9: Total number of words | J9: =J8*J7 -> 73824
C10: Total Tokens | D10: =D9*D3 -> 291720 | F10: Total tokens | G10: =G9*D3 -> 23337.6 | I10: Total tokens | J10: =J9*D3 -> 95971.2
C13: Corpus embeddings (voyage-4-lite)
C14: Component | D14: Cost/Quantity
C15: Total tokens embedded per month | D15: =D10+G10+J10 -> 411028.8
C16: Cost per 1M token | D16: 0.02
C17: Total cost for corpus embeddings | D17: =D15*D16/1000000 -> 0.008220576
C20: Lookup query embeddings
C21: Component | D21: Cost/Quantity
C22: Token per lookup query | D22: 60
C23: Total lookups per month | D23: ='Volume Sizing'!$D$19+'Volume Sizing'!$D$25 -> 1975.6
C24: Total tokens per month | D24: =D23*D22 -> 118536
C25: Cost per 1M token | D25: 0.02
C26: Total cost for lookup embeddings | D26: =D24*D25/1000000 -> 0.00237072
C29: Total cost of Embeddings | D29: =D17+D26 -> 0.010591296
C31: What embeddings are for: F1 shortlists candidate accounts for fuzzy names ('Meridian Health LLC' vs 'Meridian Healthcare') and flags likely duplicate records; F4 pulls the account's most relevant past messages into a draft. No RAG chatbot: the brief and drafts read the ledger directly. Stored in Supabase pgvector (no extra cost).
C32: Price: voyage-4-lite $0.02 per 1M tokens, with the first 200M tokens free (docs.voyageai.com/docs/pricing, checked 3 Oct 2026). At well under 1M tokens a month the free allowance covers this for years, so the billed cost is $0; the list-price cost is shown. Embeddings are optional: trigram string matching alone could replace them.

Sheet Infrastructure
B2: Infrastructure: prototype (Step 5) vs production MVP, $ per month
B4: Service | C4: Prototype on dataset | D4: Production MVP (4 sellers) | E4: Why / source (checked 4 Oct 2026)
B5: Vercel (Next.js app, API routes, cron for nightly brief) | C5: 0 | D5: 20 | E5: Prototype is live on Vercel Hobby ($0) at atliq-sales-and-crm-assistant.vercel.app. Hobby is for personal, non-commercial use, so running it for AtliQ's sales team moves to Pro: $20 a month, 1 developer seat, $20 of included usage credit, free viewer seats. vercel.com/pricing
B6: Supabase (Postgres for ledger, approvals, audit log) | C6: 0 | D6: 25 | E6: Not used in the prototype: it has no database. Seller decisions and the audit log live in the browser, and approved CRM changes export as a CSV change file. Production needs shared, durable storage for the 12-month audit log, so Supabase Pro at $25 a month stays in the plan. supabase.com/pricing
B7: Mailbox read access (Google Workspace / Microsoft 365 API) | C7: 0 | D7: 0 | E7: Uses AtliQ's existing workspace licences with a read-only scope; no send permission (PRD guardrail).
B8: Groq API account (GPT-OSS models, Whisper) | C8: 0 | D8: 0 | E8: Pay as you go per token, no platform fee. Zero data retention switched on in Groq's Data Controls. Usage on the 'Inference (Groq)' sheet.
B9: Voyage AI account (embeddings) | C9: 0 | D9: 0 | E9: Not needed: no embeddings in the current plan (see 'Embeddings').
B10: Total infrastructure | C10: =SUM(C5:C9) -> 0 | D10: =SUM(D5:D9) -> 45 | E10: Fixed cost: it does not grow with sellers until the Supabase or Vercel limits are reached (well beyond 10 sellers).

Sheet Cost Savings
D3: Doing the capture by hand: sales coordinator effort
D4: Component | E4: Quantity
D5: Sources (client emails + notes) to capture per day | E5: ='Volume Sizing'!$D$19/'Volume Sizing'!$D$16 -> 74.8
D6: Sources one coordinator can read, log and follow up per day | E6: 90 | F6: About 5 minutes per source: read, find the account, log asks and promises, set a follow-up date. Assumption.
D7: Workdays per month | E7: ='Volume Sizing'!$D$16 -> 22
D8: Sources handled per coordinator per month | E8: =E6*E7 -> 1980
D9: Total sources per month | E9: ='Volume Sizing'!$D$19 -> 1645.6
D10: Number of coordinators (FTE) required | E10: =E9/E8 -> 0.83111111
D13: Total monthly cost of a sales coordinator
D14: Component | E14: Cost
D15: Salary (sales coordinator, India) | E15: 450 | F15: Assumption: about Rs 38,000 a month for a junior sales coordinator in India (AtliQ's market).
D16: Admin cost (laptop, software, overhead) | E16: 100
D17: Total cost per coordinator per month | E17: =E15+E16 -> 550
D19: Total cost of manual capture per month | E19: =E17*E10 -> 457.11111 | F19: This is what the CRM 'update same-day' rule silently asks of the sellers today, and it failed twice (April and July).
D22: Cost for AtliQ Sales and CRM Assistant (MVP)
D23: Component | E23: Cost
D24: Inference cost (incl. 25% buffer) | E24: =SUM(Summary!E6:E10)+Summary!E12 -> 1.8956457
D25: Embeddings cost | E25: =Summary!E11 -> 0
D26: Infrastructure (Vercel Pro + Supabase Pro) | E26: =Infrastructure!$D$10 -> 45
D27: Total AtliQ Sales and CRM Assistant | E27: =E24+E25+E26 -> 46.895646
D28: Cost per seller per month | E28: =E27/'Volume Sizing'!$D$6 -> 11.723911
D30: Total Savings | E30: =E19-E27 -> 410.21547 | F30: Running cost is a small fraction of one coordinator, even before counting seller time.
D31: % Savings | E31: =E30/E19 -> 0.89740865
D34: Value not counted above
D35: Jay's reconciliation before each pipeline review | E35: About 2 hours today, target 15 minutes or less (PRD Section 12).
D36: Seller time | E36: Four sellers stop re-reading threads and typing into the CRM; the brief takes 5 minutes a morning.
D37: Pipeline protected | E37: $442.5k of valued pipeline across 8 deals sits behind a missed or at-risk AtliQ action (PRD, 10 Jul 2026). Saving one Kaveri-sized $15k deal pays for more than a year of running cost.

Sheet Sources & Assumptions
B2: Sources and assumptions
B4: Price used | C4: Value (checked 3 Oct 2026) | D4: Source
B5: Claude Haiku 4.5 (comparison) | C5: $1 input / $5 output per 1M tokens; cache read $0.10; batch $0.50 / $2.50; min cacheable prefix 4,096 tokens | D5: https://platform.claude.com/docs/en/about-claude/pricing
B6: Claude Sonnet 5.5 (comparison) | C6: $2 input / $10 output per 1M tokens; cache read $0.20; batch $1 / $5; min cacheable prefix 512 tokens | D6: https://platform.claude.com/docs/en/about-claude/pricing
B7: Claude Opus 5.5 (comparison) | C7: $4 input / $20 output per 1M tokens; cache read $0.20 (0.05x); batch $2 / $10 | D7: https://platform.claude.com/docs/en/about-claude/pricing
B8: Prompt caching multipliers | C8: 5-minute write 1.25x, 1-hour write 2x, read 0.1x base input (0.05x on Opus 5.5) | D8: https://platform.claude.com/docs/en/about-claude/pricing#prompt-caching
B9: Minimum cacheable prompt length | C9: 512 tokens for Sonnet 5.5 and Opus 5.5; 4,096 tokens for Haiku 4.5 | D9: https://platform.claude.com/docs/en/build-with-claude/prompt-caching
B10: Tokenizer note | C10: Claude 4.7 and later models produce about 30% more tokens for the same text | D10: https://platform.claude.com/docs/en/about-claude/pricing
B11: Voyage voyage-4-lite embeddings (not used) | C11: $0.02 per 1M tokens; first 200M tokens free | D11: https://docs.voyageai.com/docs/pricing
B12: OpenAI gpt-4o-mini-transcribe (replaced by Groq Whisper) | C12: Estimated $0.003 per minute (whisper-1 and gpt-4o-transcribe $0.006) | D12: https://developers.openai.com/api/docs/pricing
B13: Vercel | C13: See the 4 Oct 2026 row below | D13: https://vercel.com/pricing
B14: Supabase | C14: Free $0 (pauses after 1 week inactive); Pro from $25 per month | D14: https://supabase.com/pricing
B17: Key assumptions
B18: Provider | C18: Groq for all text tasks (gpt-oss-20b and gpt-oss-120b), matching the live prototype. Zero data retention enabled in Groq's Data Controls; Groq does not use inference data for training. The Claude API remains a coded fallback and the comparison on the 'Inference' sheet.
B19: Data residency | C19: Groq retains any customer data it keeps in Google Cloud in the United States, and zero data retention disables batch. Clients like FinEdge want in-country processing, so data residency is an open question for Pranav before beta (PRD section 16).
B20: Volumes | C20: PRD NFR sizing: about 1,500 client emails and 150 meeting notes a month for 4 sellers and 200 accounts. Derivation on the 'Volume Sizing' sheet.
B21: Token sizes | C21: Measured from the dataset (avg 134 words per email, 99 per note), raised to 150 and 120. GPT-OSS: 1.3 tokens per word; Claude comparison: 1.69. Prompt sizes are estimates; reasoning-token allowances are assumptions. Replace both with measured usage from the prototype logs.
B22: Workdays | C22: 22 per month; ingestion runs whenever mail arrives, the brief only on workdays.
B23: Exchange rate | C23: Not needed: every price is in USD. The coordinator salary on 'Cost Savings' is an assumption in USD.
B24: What is not costed | C24: Engineering time to build and maintain, CRM vendor fees (already paid), and the sellers' own Google or Microsoft licences.
B26: Prices added 4 Oct 2026 (chosen stack)
B27: Groq gpt-oss-20b | C27: $0.075 input / $0.0375 cached input / $0.30 output per 1M tokens | D27: https://console.groq.com/docs/model/openai/gpt-oss-20b
B28: Groq gpt-oss-120b | C28: $0.15 input / $0.075 cached input / $0.60 output per 1M tokens | D28: https://console.groq.com/docs/model/openai/gpt-oss-120b
B29: Groq prompt caching | C29: Automatic on GPT-OSS models, no extra fee, 50% off cached input, expires after 2 hours unused | D29: https://console.groq.com/docs/prompt-caching
B30: Groq Batch API | C30: 50% off, 24-hour to 7-day window; does not stack with caching; disabled under zero data retention | D30: https://console.groq.com/docs/batch
B31: Groq data handling | C31: Inference data not retained by default; up to 30 days for abuse monitoring unless ZDR is on; stored in the US | D31: https://console.groq.com/docs/your-data
B32: Groq whisper-large-v3-turbo | C32: $0.04 per audio hour (minimum 10 seconds per request) | D32: https://console.groq.com/docs/model/whisper-large-v3-turbo
B33: Vercel | C33: Hobby $0 (non-commercial); Pro $20 per month with $20 included usage credit and 1 developer seat | D33: https://vercel.com/pricing
